Workbook

Sheet Raw_Data
A1: title | B1: magnitude | C1: date_time | D1: cdi | E1: mmi | F1: alert | G1: tsunami | H1: sig | I1: net | J1: nst | K1: dmin | L1: gap | M1: magType | N1: depth | O1: latitude | P1: longitude | Q1: location | R1: continent | S1: country | T1: converted_datetime | U1: title_pattern | V1: magType_normalized | W1: duplicate_flag
A2: M 6.5 - 42 km W of Sola, Vanuatu | B2: 6.5 | C2: 16/08/2023 12:47 | D2: 7 | E2: 4 | F2: green | G2: 0 | H2: 657 | I2: us | J2: 114 | K2: 7.177 | L2: 25 | M2: mww | N2: 192.955 | O2: -13.8814 | P2: 167.158 | Q2: Sola, Vanuatu | S2: Vanuatu | T2: =DATE(VALUE(MID(C2,7,4)),VALUE(MID(C2,4,2)),VALUE(MID(C2,1,2)))+TIME(VALUE(MID(C2,12,2)),VALUE(MID(C2,15,2)),0) -> 45154.533 | U2: =IF(AND(ISNUMBER(VALUE(MID(A2,7,1))),ISNUMBER(SEARCH("km",A2)),ISNUMBER(SEARCH("of",A2))),"Distance-location","Named-region") -> Named-region | V2: =LOWER(M2) -> mww | W2: =IF(COUNTIFS($A$2:$A$1001,A2,$C$2:$C$1001,C2)>1,"Duplicate","Unique") -> Unique
A3: M 6.5 - 43 km S of Intipucá, El Salvador | B3: 6.5 | C3: 19/07/2023 00:22 | D3: 8 | E3: 6 | F3: yellow | G3: 0 | H3: 775 | I3: us | J3: 92 | K3: 0.679 | L3: 40 | M3: mww | N3: 69.727 | O3: 12.814 | P3: -88.1265 | Q3: Intipucá, El Salvador | T3: =DATE(VALUE(MID(C3,7,4)),VALUE(MID(C3,4,2)),VALUE(MID(C3,1,2)))+TIME(VALUE(MID(C3,12,2)),VALUE(MID(C3,15,2)),0) -> 45126.015 | U3: =IF(AND(ISNUMBER(VALUE(MID(A3,7,1))),ISNUMBER(SEARCH("km",A3)),ISNUMBER(SEARCH("of",A3))),"Distance-location","Named-region") -> Named-region | V3: =LOWER(M3) -> mww | W3: =IF(COUNTIFS($A$2:$A$1001,A3,$C$2:$C$1001,C3)>1,"Duplicate","Unique") -> Unique
A4: M 6.6 - 25 km ESE of Loncopué, Argentina | B4: 6.6 | C4: 17/07/2023 03:05 | D4: 7 | E4: 5 | F4: green | G4: 0 | H4: 899 | I4: us | J4: 70 | K4: 1.634 | L4: 28 | M4: mww | N4: 171.371 | O4: -38.1911 | P4: -70.3731 | Q4: Loncopué, Argentina | R4: South America | S4: Argentina | T4: =DATE(VALUE(MID(C4,7,4)),VALUE(MID(C4,4,2)),VALUE(MID(C4,1,2)))+TIME(VALUE(MID(C4,12,2)),VALUE(MID(C4,15,2)),0) -> 45124.128 | U4: =IF(AND(ISNUMBER(VALUE(MID(A4,7,1))),ISNUMBER(SEARCH("km",A4)),ISNUMBER(SEARCH("of",A4))),"Distance-location","Named-region") -> Named-region | V4: =LOWER(M4) -> mww | W4: =IF(COUNTIFS($A$2:$A$1001,A4,$C$2:$C$1001,C4)>1,"Duplicate","Unique") -> Unique
A5: M 7.2 - 98 km S of Sand Point, Alaska | B5: 7.2 | C5: 16/07/2023 06:48 | D5: 6 | E5: 6 | F5: green | G5: 1 | H5: 860 | I5: us | J5: 173 | K5: 0.907 | L5: 36 | M5: mww | N5: 32.571 | O5: 54.3844 | P5: -160.699 | Q5: Sand Point, Alaska | T5: =DATE(VALUE(MID(C5,7,4)),VALUE(MID(C5,4,2)),VALUE(MID(C5,1,2)))+TIME(VALUE(MID(C5,12,2)),VALUE(MID(C5,15,2)),0) -> 45123.283 | U5: =IF(AND(ISNUMBER(VALUE(MID(A5,7,1))),ISNUMBER(SEARCH("km",A5)),ISNUMBER(SEARCH("of",A5))),"Distance-location","Named-region") -> Named-region | V5: =LOWER(M5) -> mww | W5: =IF(COUNTIFS($A$2:$A$1001,A5,$C$2:$C$1001,C5)>1,"Duplicate","Unique") -> Unique
A6: M 7.3 - Alaska Peninsula | B6: 7.3 | C6: 16/07/2023 06:48 | D6: 0 | E6: 5 | G6: 1 | H6: 820 | I6: at | J6: 79 | K6: 0.879451 | L6: 172.8 | M6: Mi | N6: 21 | O6: 54.49 | P6: -160.796 | Q6: Alaska Peninsula | T6: =DATE(VALUE(MID(C6,7,4)),VALUE(MID(C6,4,2)),VALUE(MID(C6,1,2)))+TIME(VALUE(MID(C6,12,2)),VALUE(MID(C6,15,2)),0) -> 45123.283 | U6: =IF(AND(ISNUMBER(VALUE(MID(A6,7,1))),ISNUMBER(SEARCH("km",A6)),ISNUMBER(SEARCH("of",A6))),"Distance-location","Named-region") -> Named-region | V6: =LOWER(M6) -> mi | W6: =IF(COUNTIFS($A$2:$A$1001,A6,$C$2:$C$1001,C6)>1,"Duplicate","Unique") -> Unique
A7: M 6.6 - 277 km NNE of Codrington, Antigua and Barbuda | B7: 6.6 | C7: 10/07/2023 20:28 | D7: 5 | E7: 4 | F7: green | G7: 1 | H7: 802 | I7: us | J7: 95 | K7: 2.454 | L7: 37 | M7: mww | N7: 10 | O7: 20.0196 | P7: -61.0955 | Q7: Codrington, Antigua and Barbuda | T7: =DATE(VALUE(MID(C7,7,4)),VALUE(MID(C7,4,2)),VALUE(MID(C7,1,2)))+TIME(VALUE(MID(C7,12,2)),VALUE(MID(C7,15,2)),0) -> 45117.853 | U7: =IF(AND(ISNUMBER(VALUE(MID(A7,7,1))),ISNUMBER(SEARCH("km",A7)),ISNUMBER(SEARCH("of",A7))),"Distance-location","Named-region") -> Named-region | V7: =LOWER(M7) -> mww | W7: =IF(COUNTIFS($A$2:$A$1001,A7,$C$2:$C$1001,C7)>1,"Duplicate","Unique") -> Unique
A8: M 6.9 - Tonga | B8: 6.9 | C8: 02/07/2023 10:27 | D8: 4 | E8: 4 | F8: green | G8: 1 | H8: 741 | I8: us | J8: 136 | K8: 1.179 | L8: 23 | M8: mww | N8: 229 | O8: -17.853 | P8: -174.937 | Q8: Tonga | T8: =DATE(VALUE(MID(C8,7,4)),VALUE(MID(C8,4,2)),VALUE(MID(C8,1,2)))+TIME(VALUE(MID(C8,12,2)),VALUE(MID(C8,15,2)),0) -> 45109.435 | U8: =IF(AND(ISNUMBER(VALUE(MID(A8,7,1))),ISNUMBER(SEARCH("km",A8)),ISNUMBER(SEARCH("of",A8))),"Distance-location","Named-region") -> Named-region | V8: =LOWER(M8) -> mww | W8: =IF(COUNTIFS($A$2:$A$1001,A8,$C$2:$C$1001,C8)>1,"Duplicate","Unique") -> Unique
A9: M 7.2 - south of the Fiji Islands | B9: 7.2 | C9: 15/06/2023 18:06 | D9: 8 | E9: 6 | F9: green | G9: 1 | H9: 804 | I9: us | J9: 85 | K9: 2.59 | L9: 24 | M9: mww | N9: 167.404 | O9: -22.9824 | P9: -177.208 | Q9: the Fiji Islands | T9: =DATE(VALUE(MID(C9,7,4)),VALUE(MID(C9,4,2)),VALUE(MID(C9,1,2)))+TIME(VALUE(MID(C9,12,2)),VALUE(MID(C9,15,2)),0) -> 45092.754 | U9: =IF(AND(ISNUMBER(VALUE(MID(A9,7,1))),ISNUMBER(SEARCH("km",A9)),ISNUMBER(SEARCH("of",A9))),"Distance-location","Named-region") -> Named-region | V9: =LOWER(M9) -> mww | W9: =IF(COUNTIFS($A$2:$A$1001,A9,$C$2:$C$1001,C9)>1,"Duplicate","Unique") -> Unique
A10: M 6.6 - Panama-Colombia border region | B10: 6.6 | C10: 25/05/2023 03:05 | D10: 6 | E10: 6 | F10: green | G10: 1 | H10: 733 | I10: us | J10: 50 | K10: 2.163 | L10: 129 | M10: mww | N10: 10 | O10: 8.8894 | P10: -77.1231 | Q10: Panama-Colombia border region | S10: Colombia | T10: =DATE(VALUE(MID(C10,7,4)),VALUE(MID(C10,4,2)),VALUE(MID(C10,1,2)))+TIME(VALUE(MID(C10,12,2)),VALUE(MID(C10,15,2)),0) -> 45071.128 | U10: =IF(AND(ISNUMBER(VALUE(MID(A10,7,1))),ISNUMBER(SEARCH("km",A10)),ISNUMBER(SEARCH("of",A10))),"Distance-location","Named-region") -> Named-region | V10: =LOWER(M10) -> mww | W10: =IF(COUNTIFS($A$2:$A$1001,A10,$C$2:$C$1001,C10)>1,"Duplicate","Unique") -> Unique
A11: M 7.1 - southeast of the Loyalty Islands | B11: 7.1 | C11: 20/05/2023 01:51 | D11: 3 | E11: 4 | F11: green | G11: 1 | H11: 777 | I11: us | J11: 98 | K11: 2.812 | L11: 56 | M11: mww | N11: 35.981 | O11: -23.0622 | P11: 170.456 | Q11: the Loyalty Islands | T11: =DATE(VALUE(MID(C11,7,4)),VALUE(MID(C11,4,2)),VALUE(MID(C11,1,2)))+TIME(VALUE(MID(C11,12,2)),VALUE(MID(C11,15,2)),0) -> 45066.077 | U11: =IF(AND(ISNUMBER(VALUE(MID(A11,7,1))),ISNUMBER(SEARCH("km",A11)),ISNUMBER(SEARCH("of",A11))),"Distance-location","Named-region") -> Named-region | V11: =LOWER(M11) -> mww | W11: =IF(COUNTIFS($A$2:$A$1001,A11,$C$2:$C$1001,C11)>1,"Duplicate","Unique") -> Unique
A12: M 7.7 - southeast of the Loyalty Islands | B12: 7.7 | C12: 19/05/2023 02:57 | D12: 5 | E12: 4 | F12: green | G12: 1 | H12: 927 | I12: us | J12: 277 | K12: 3.111 | L12: 15 | M12: mww | N12: 18.027 | O12: -23.2286 | P12: 170.694 | Q12: the Loyalty Islands | T12: =DATE(VALUE(MID(C12,7,4)),VALUE(MID(C12,4,2)),VALUE(MID(C12,1,2)))+TIME(VALUE(MID(C12,12,2)),VALUE(MID(C12,15,2)),0) -> 45065.123 | U12: =IF(AND(ISNUMBER(VALUE(MID(A12,7,1))),ISNUMBER(SEARCH("km",A12)),ISNUMBER(SEARCH("of",A12))),"Distance-location","Named-region") -> Named-region | V12: =LOWER(M12) -> mww | W12: =IF(COUNTIFS($A$2:$A$1001,A12,$C$2:$C$1001,C12)>1,"Duplicate","Unique") -> Unique
A13: M 7.6 - 95 km WNW of Hihifo, Tonga | B13: 7.6 | C13: 10/05/2023 16:02 | D13: 8 | E13: 6 | F13: green | G13: 1 | H13: 907 | I13: us | J13: 111 | K13: 3.631 | L13: 17 | M13: mww | N13: 210.097 | O13: -15.6002 | P13: -174.608 | Q13: Hihifo, Tonga | T13: =DATE(VALUE(MID(C13,7,4)),VALUE(MID(C13,4,2)),VALUE(MID(C13,1,2)))+TIME(VALUE(MID(C13,12,2)),VALUE(MID(C13,15,2)),0) -> 45056.668 | U13: =IF(AND(ISNUMBER(VALUE(MID(A13,7,1))),ISNUMBER(SEARCH("km",A13)),ISNUMBER(SEARCH("of",A13))),"Distance-location","Named-region") -> Named-region | V13: =LOWER(M13) -> mww | W13: =IF(COUNTIFS($A$2:$A$1001,A13,$C$2:$C$1001,C13)>1,"Duplicate","Unique") -> Unique
A14: M 6.6 - south of the Fiji Islands | B14: 6.6 | C14: 28/04/2023 03:13 | D14: 0 | E14: 2 | F14: green | G14: 0 | H14: 670 | I14: us | J14: 52 | K14: 5.123 | L14: 50 | M14: mww | N14: 598.467 | O14: -25.2657 | P14: 178.424 | Q14: the Fiji Islands | T14: =DATE(VALUE(MID(C14,7,4)),VALUE(MID(C14,4,2)),VALUE(MID(C14,1,2)))+TIME(VALUE(MID(C14,12,2)),VALUE(MID(C14,15,2)),0) -> 45044.134 | U14: =IF(AND(ISNUMBER(VALUE(MID(A14,7,1))),ISNUMBER(SEARCH("km",A14)),ISNUMBER(SEARCH("of",A14))),"Distance-location","Named-region") -> Named-region | V14: =LOWER(M14) -> mww | W14: =IF(COUNTIFS($A$2:$A$1001,A14,$C$2:$C$1001,C14)>1,"Duplicate","Unique") -> Unique
A15: M 7.1 - 170 km SSE of Teluk Dalam, Indonesia | B15: 7.1 | C15: 24/04/2023 20:00 | D15: 9 | E15: 7 | F15: green | G15: 0 | H15: 838 | I15: us | J15: 70 | K15: 2.282 | L15: 58 | M15: mww | N15: 15.462 | O15: -0.781 | P15: 98.5339 | Q15: Teluk Dalam, Indonesia | S15: Indonesia | T15: =DATE(VALUE(MID(C15,7,4)),VALUE(MID(C15,4,2)),VALUE(MID(C15,1,2)))+TIME(VALUE(MID(C15,12,2)),VALUE(MID(C15,15,2)),0) -> 45040.833 | U15: =IF(AND(ISNUMBER(VALUE(MID(A15,7,1))),ISNUMBER(SEARCH("km",A15)),ISNUMBER(SEARCH("of",A15))),"Distance-location","Named-region") -> Named-region | V15: =LOWER(M15) -> mww | W15: =IF(COUNTIFS($A$2:$A$1001,A15,$C$2:$C$1001,C15)>1,"Duplicate","Unique") -> Unique
A16: M 7.1 - Kermadec Islands, New Zealand | B16: 7.1 | C16: 24/04/2023 00:41 | D16: 8 | E16: 7 | F16: green | G16: 1 | H16: 777 | I16: us | J16: 126 | K16: 0.708 | L16: 23 | M16: mww | N16: 43.063 | O16: -30.0249 | P16: -177.897 | Q16: Kermadec Islands, New Zealand | T16: =DATE(VALUE(MID(C16,7,4)),VALUE(MID(C16,4,2)),VALUE(MID(C16,1,2)))+TIME(VALUE(MID(C16,12,2)),VALUE(MID(C16,15,2)),0) -> 45040.028 | U16: =IF(AND(ISNUMBER(VALUE(MID(A16,7,1))),ISNUMBER(SEARCH("km",A16)),ISNUMBER(SEARCH("of",A16))),"Distance-location","Named-region") -> Named-region | V16: =LOWER(M16) -> mww | W16: =IF(COUNTIFS($A$2:$A$1001,A16,$C$2:$C$1001,C16)>1,"Duplicate","Unique") -> Unique
A17: M 6.7 - south of the Fiji Islands | B17: 6.7 | C17: 18/04/2023 04:31 | D17: 0 | E17: 3 | F17: green | G17: 1 | H17: 691 | I17: us | J17: 166 | K17: 4.719 | L17: 10 | M17: mww | N17: 595.854 | O17: -22.2844 | P17: 179.391 | Q17: the Fiji Islands | T17: =DATE(VALUE(MID(C17,7,4)),VALUE(MID(C17,4,2)),VALUE(MID(C17,1,2)))+TIME(VALUE(MID(C17,12,2)),VALUE(MID(C17,15,2)),0) -> 45034.188 | U17: =IF(AND(ISNUMBER(VALUE(MID(A17,7,1))),ISNUMBER(SEARCH("km",A17)),ISNUMBER(SEARCH("of",A17))),"Distance-location","Named-region") -> Named-region | V17: =LOWER(M17) -> mww | W17: =IF(COUNTIFS($A$2:$A$1001,A17,$C$2:$C$1001,C17)>1,"Duplicate","Unique") -> Unique
A18: M 7.0 - 96 km N of Tuban, Indonesia | B18: 7 | C18: 14/04/2023 09:55 | D18: 5 | E18: 3 | F18: green | G18: 0 | H18: 818 | I18: us | J18: 131 | K18: 1.881 | L18: 31 | M18: mww | N18: 594.028 | O18: -6.0255 | P18: 112.033 | Q18: Tuban, Indonesia | S18: Indonesia | T18: =DATE(VALUE(MID(C18,7,4)),VALUE(MID(C18,4,2)),VALUE(MID(C18,1,2)))+TIME(VALUE(MID(C18,12,2)),VALUE(MID(C18,15,2)),0) -> 45030.413 | U18: =IF(AND(ISNUMBER(VALUE(MID(A18,7,1))),ISNUMBER(SEARCH("km",A18)),ISNUMBER(SEARCH("of",A18))),"Distance-location","Named-region") -> Named-region | V18: =LOWER(M18) -> mww | W18: =IF(COUNTIFS($A$2:$A$1001,A18,$C$2:$C$1001,C18)>1,"Duplicate","Unique") -> Unique
A19: M 6.5 - near the east coast of the Kamchatka Peninsula, Russia | B19: 6.5 | C19: 03/04/2023 03:06 | D19: 7 | E19: 6 | F19: yellow | G19: 1 | H19: 655 | I19: us | J19: 104 | K19: 0.266 | L19: 30 | M19: mww | N19: 105.631 | O19: 52.7772 | P19: 158.484 | Q19: the Kamchatka Peninsula, Russia | R19: Asia | S19: Russian Federation (the) | T19: =DATE(VALUE(MID(C19,7,4)),VALUE(MID(C19,4,2)),VALUE(MID(C19,1,2)))+TIME(VALUE(MID(C19,12,2)),VALUE(MID(C19,15,2)),0) -> 45019.129 | U19: =IF(AND(ISNUMBER(VALUE(MID(A19,7,1))),ISNUMBER(SEARCH("km",A19)),ISNUMBER(SEARCH("of",A19))),"Distance-location","Named-region") -> Named-region | V19: =LOWER(M19) -> mww | W19: =IF(COUNTIFS($A$2:$A$1001,A19,$C$2:$C$1001,C19)>1,"Duplicate","Unique") -> Unique
A20: M 7.0 - New Guinea, Papua New Guinea | B20: 7 | C20: 02/04/2023 18:04 | D20: 7 | E20: 7 | F20: green | G20: 1 | H20: 781 | I20: us | J20: 105 | K20: 6.45 | L20: 31 | M20: mww | N20: 62.603 | O20: -4.2924 | P20: 143.155 | Q20: New Guinea, Papua New Guinea | R20: Asia | S20: Papua New Guinea | T20: =DATE(VALUE(MID(C20,7,4)),VALUE(MID(C20,4,2)),VALUE(MID(C20,1,2)))+TIME(VALUE(MID(C20,12,2)),VALUE(MID(C20,15,2)),0) -> 45018.753 | U20: =IF(AND(ISNUMBER(VALUE(MID(A20,7,1))),ISNUMBER(SEARCH("km",A20)),ISNUMBER(SEARCH("of",A20))),"Distance-location","Named-region") -> Named-region | V20: =LOWER(M20) -> mww | W20: =IF(COUNTIFS($A$2:$A$1001,A20,$C$2:$C$1001,C20)>1,"Duplicate","Unique") -> Unique
A21: M 6.5 - 84 km NNW of San Antonio de los Cobres, Argentina | B21: 6.5 | C21: 22/03/2023 16:00 | D21: 4 | E21: 4 | F21: green | G21: 0 | H21: 656 | I21: us | J21: 97 | K21: 1.622 | L21: 33 | M21: mww | N21: 209.976 | O21: -23.4797 | P21: -66.5108 | Q21: San Antonio de los Cobres, Argentina | R21: South America | S21: Argentina | T21: =DATE(VALUE(MID(C21,7,4)),VALUE(MID(C21,4,2)),VALUE(MID(C21,1,2)))+TIME(VALUE(MID(C21,12,2)),VALUE(MID(C21,15,2)),0) -> 45007.667 | U21: =IF(AND(ISNUMBER(VALUE(MID(A21,7,1))),ISNUMBER(SEARCH("km",A21)),ISNUMBER(SEARCH("of",A21))),"Distance-location","Named-region") -> Named-region | V21: =LOWER(M21) -> mww | W21: =IF(COUNTIFS($A$2:$A$1001,A21,$C$2:$C$1001,C21)>1,"Duplicate","Unique") -> Unique
A22: M 6.5 - 40 km SSE of Jurm, Afghanistan | B22: 6.5 | C22: 21/03/2023 16:47 | D22: 7 | E22: 5 | F22: green | G22: 0 | H22: 1350 | I22: us | J22: 134 | K22: 2.53 | L22: 13 | M22: mww | N22: 187.589 | O22: 36.5227 | P22: 70.9787 | Q22: Jurm, Afghanistan | R22: Asia | S22: Afghanistan | T22: =DATE(VALUE(MID(C22,7,4)),VALUE(MID(C22,4,2)),VALUE(MID(C22,1,2)))+TIME(VALUE(MID(C22,12,2)),VALUE(MID(C22,15,2)),0) -> 45006.699 | U22: =IF(AND(ISNUMBER(VALUE(MID(A22,7,1))),ISNUMBER(SEARCH("km",A22)),ISNUMBER(SEARCH("of",A22))),"Distance-location","Named-region") -> Named-region | V22: =LOWER(M22) -> mww | W22: =IF(COUNTIFS($A$2:$A$1001,A22,$C$2:$C$1001,C22)>1,"Duplicate","Unique") -> Unique
A23: M 6.8 - near the coast of Ecuador | B23: 6.8 | C23: 18/03/2023 17:12 | D23: 9 | E23: 7 | F23: orange | G23: 1 | H23: 1159 | I23: us | J23: 152 | K23: 0.709 | L23: 28 | M23: mww | N23: 65.842 | O23: -2.851 | P23: -79.8001 | Q23: Ecuador | R23: South America | S23: Ecuador | T23: =DATE(VALUE(MID(C23,7,4)),VALUE(MID(C23,4,2)),VALUE(MID(C23,1,2)))+TIME(VALUE(MID(C23,12,2)),VALUE(MID(C23,15,2)),0) -> 45003.717 | U23: =IF(AND(ISNUMBER(VALUE(MID(A23,7,1))),ISNUMBER(SEARCH("km",A23)),ISNUMBER(SEARCH("of",A23))),"Distance-location","Named-region") -> Named-region | V23: =LOWER(M23) -> mww | W23: =IF(COUNTIFS($A$2:$A$1001,A23,$C$2:$C$1001,C23)>1,"Duplicate","Unique") -> Unique
A24: M 7.0 - Kermadec Islands region | B24: 7 | C24: 16/03/2023 00:56 | D24: 8 | E24: 5 | F24: green | G24: 1 | H24: 756 | I24: us | J24: 116 | K24: 1.789 | L24: 22 | M24: mww | N24: 22.065 | O24: -30.1147 | P24: -176.112 | Q24: Kermadec Islands region | T24: =DATE(VALUE(MID(C24,7,4)),VALUE(MID(C24,4,2)),VALUE(MID(C24,1,2)))+TIME(VALUE(MID(C24,12,2)),VALUE(MID(C24,15,2)),0) -> 45001.039 | U24: =IF(AND(ISNUMBER(VALUE(MID(A24,7,1))),ISNUMBER(SEARCH("km",A24)),ISNUMBER(SEARCH("of",A24))),"Distance-location","Named-region") -> Named-region | V24: =LOWER(M24) -> mww | W24: =IF(COUNTIFS($A$2:$A$1001,A24,$C$2:$C$1001,C24)>1,"Duplicate","Unique") -> Unique
A25: M 6.9 - Kermadec Islands, New Zealand | B25: 6.9 | C25: 04/03/2023 06:41 | D25: 5 | E25: 5 | F25: green | G25: 1 | H25: 735 | I25: us | J25: 108 | K25: 0.784 | L25: 18 | M25: mww | N25: 205.681 | O25: -29.4748 | P25: -178.787 | Q25: Kermadec Islands, New Zealand | T25: =DATE(VALUE(MID(C25,7,4)),VALUE(MID(C25,4,2)),VALUE(MID(C25,1,2)))+TIME(VALUE(MID(C25,12,2)),VALUE(MID(C25,15,2)),0) -> 44989.278 | U25: =IF(AND(ISNUMBER(VALUE(MID(A25,7,1))),ISNUMBER(SEARCH("km",A25)),ISNUMBER(SEARCH("of",A25))),"Distance-location","Named-region") -> Named-region | V25: =LOWER(M25) -> mww | W25: =IF(COUNTIFS($A$2:$A$1001,A25,$C$2:$C$1001,C25)>1,"Duplicate","Unique") -> Unique
A26: M 6.5 - 86 km WSW of Port-Olry, Vanuatu | B26: 6.5 | C26: 02/03/2023 18:04 | D26: 7 | E26: 6 | F26: green | G26: 1 | H26: 653 | I26: us | J26: 66 | K26: 5.483 | L26: 45 | M26: mww | N26: 10 | O26: -15.3597 | P26: 166.385 | Q26: Port-Olry, Vanuatu | T26: =DATE(VALUE(MID(C26,7,4)),VALUE(MID(C26,4,2)),VALUE(MID(C26,1,2)))+TIME(VALUE(MID(C26,12,2)),VALUE(MID(C26,15,2)),0) -> 44987.753 | U26: =IF(AND(ISNUMBER(VALUE(MID(A26,7,1))),ISNUMBER(SEARCH("km",A26)),ISNUMBER(SEARCH("of",A26))),"Distance-location","Named-region") -> Named-region | V26: =LOWER(M26) -> mww | W26: =IF(COUNTIFS($A$2:$A$1001,A26,$C$2:$C$1001,C26)>1,"Duplicate","Unique") -> Unique
A27: M 6.5 - 108 km NW of Kimbe, Papua New Guinea | B27: 6.5 | C27: 01/03/2023 05:36 | D27: 4 | E27: 2 | F27: green | G27: 1 | H27: 652 | I27: us | J27: 115 | K27: 2.739 | L27: 20 | M27: mww | N27: 598.925 | O27: -4.8138 | P27: 149.487 | Q27: Kimbe, Papua New Guinea | S27: Papua New Guinea | T27: =DATE(VALUE(MID(C27,7,4)),VALUE(MID(C27,4,2)),VALUE(MID(C27,1,2)))+TIME(VALUE(MID(C27,12,2)),VALUE(MID(C27,15,2)),0) -> 44986.233 | U27: =IF(AND(ISNUMBER(VALUE(MID(A27,7,1))),ISNUMBER(SEARCH("km",A27)),ISNUMBER(SEARCH("of",A27))),"Distance-location","Named-region") -> Named-region | V27: =LOWER(M27) -> mww | W27: =IF(COUNTIFS($A$2:$A$1001,A27,$C$2:$C$1001,C27)>1,"Duplicate","Unique") -> Unique
A28: M 6.8 - 67 km W of Murghob, Tajikistan | B28: 6.8 | C28: 23/02/2023 00:37 | D28: 9 | E28: 7 | F28: green | G28: 0 | H28: 737 | I28: us | J28: 128 | K28: 1.783 | L28: 20 | M28: mww | N28: 20.522 | O28: 38.0726 | P28: 73.2077 | Q28: Murghob, Tajikistan | R28: Asia | S28: Tajikistan | T28: =DATE(VALUE(MID(C28,7,4)),VALUE(MID(C28,4,2)),VALUE(MID(C28,1,2)))+TIME(VALUE(MID(C28,12,2)),VALUE(MID(C28,15,2)),0) -> 44980.026 | U28: =IF(AND(ISNUMBER(VALUE(MID(A28,7,1))),ISNUMBER(SEARCH("km",A28)),ISNUMBER(SEARCH("of",A28))),"Distance-location","Named-region") -> Named-region | V28: =LOWER(M28) -> mww | W28: =IF(COUNTIFS($A$2:$A$1001,A28,$C$2:$C$1001,C28)>1,"Duplicate","Unique") -> Unique
A29: M 7.5 - 4 km SSE of Ekinözü, Turkey | B29: 7.5 | C29: 06/02/2023 10:24 | D29: 9 | E29: 9 | F29: orange | G29: 0 | H29: 1411 | I29: us | J29: 135 | K29: 0.85 | L29: 17 | M29: mww | N29: 10 | O29: 38.0235 | P29: 37.203 | Q29: Ekinözü, Turkey | R29: Asia | S29: Turkiye | T29: =DATE(VALUE(MID(C29,7,4)),VALUE(MID(C29,4,2)),VALUE(MID(C29,1,2)))+TIME(VALUE(MID(C29,12,2)),VALUE(MID(C29,15,2)),0) -> 44963.433 | U29: =IF(AND(ISNUMBER(VALUE(MID(A29,7,1))),ISNUMBER(SEARCH("km",A29)),ISNUMBER(SEARCH("of",A29))),"Distance-location","Named-region") -> Named-region | V29: =LOWER(M29) -> mww | W29: =IF(COUNTIFS($A$2:$A$1001,A29,$C$2:$C$1001,C29)>1,"Duplicate","Unique") -> Unique
A30: M 6.7 - 18 km ESE of Nurdağı, Turkey | B30: 6.7 | C30: 06/02/2023 01:28 | D30: 9 | E30: 8 | F30: yellow | G30: 0 | H30: 800 | I30: us | J30: 108 | K30: 0.218 | L30: 44 | M30: mww | N30: 14.497 | O30: 37.4135 | P30: 36.8306 | Q30: Nurdağı, Turkey | R30: Asia | S30: Turkiye | T30: =DATE(VALUE(MID(C30,7,4)),VALUE(MID(C30,4,2)),VALUE(MID(C30,1,2)))+TIME(VALUE(MID(C30,12,2)),VALUE(MID(C30,15,2)),0) -> 44963.061 | U30: =IF(AND(ISNUMBER(VALUE(MID(A30,7,1))),ISNUMBER(SEARCH("km",A30)),ISNUMBER(SEARCH("of",A30))),"Distance-location","Named-region") -> Named-region | V30: =LOWER(M30) -> mww | W30: =IF(COUNTIFS($A$2:$A$1001,A30,$C$2:$C$1001,C30)>1,"Duplicate","Unique") -> Unique
A31: M 7.8 - Central Turkey | B31: 7.8 | C31: 06/02/2023 01:17 | D31: 9 | E31: 9 | F31: red | G31: 0 | H31: 2910 | I31: us | J31: 118 | K31: 1.919 | L31: 32 | M31: mww | N31: 17.925 | O31: 37.2012 | P31: 36.9997 | Q31: Central Turkey | R31: Asia | S31: Turkiye | T31: =DATE(VALUE(MID(C31,7,4)),VALUE(MID(C31,4,2)),VALUE(MID(C31,1,2)))+TIME(VALUE(MID(C31,12,2)),VALUE(MID(C31,15,2)),0) -> 44963.053 | U31: =IF(AND(ISNUMBER(VALUE(MID(A31,7,1))),ISNUMBER(SEARCH("km",A31)),ISNUMBER(SEARCH("of",A31))),"Distance-location","Named-region") -> Named-region | V31: =LOWER(M31) -> mww | W31: =IF(COUNTIFS($A$2:$A$1001,A31,$C$2:$C$1001,C31)>1,"Duplicate","Unique") -> Unique
A32: M 6.8 - | B32: 6.8 | C32: 20/01/2023 22:09 | D32: 4 | E32: 3 | F32: green | G32: 0 | H32: 718 | I32: us | J32: 60 | K32: 5.129 | L32: 61 | M32: mww | N32: 610.671 | O32: -26.7209 | P32: -63.0394 | R32: South America | S32: Argentina | T32: =DATE(VALUE(MID(C32,7,4)),VALUE(MID(C32,4,2)),VALUE(MID(C32,1,2)))+TIME(VALUE(MID(C32,12,2)),VALUE(MID(C32,15,2)),0) -> 44946.923 | U32: =IF(AND(ISNUMBER(VALUE(MID(A32,7,1))),ISNUMBER(SEARCH("km",A32)),ISNUMBER(SEARCH("of",A32))),"Distance-location","Named-region") -> Named-region | V32: =LOWER(M32) -> mww | W32: =IF(COUNTIFS($A$2:$A$1001,A32,$C$2:$C$1001,C32)>1,"Duplicate","Unique") -> Unique
A33: M 7.0 - 153 km NW of Tobelo, Indonesia | B33: 7 | C33: 18/01/2023 06:06 | D33: 3 | E33: 5 | F33: green | G33: 1 | H33: 756 | I33: us | J33: 130 | K33: 1.974 | L33: 17 | M33: mwc | N33: 28.566 | O33: 2.7401 | P33: 127.051 | Q33: Tobelo, Indonesia | S33: Indonesia | T33: =DATE(VALUE(MID(C33,7,4)),VALUE(MID(C33,4,2)),VALUE(MID(C33,1,2)))+TIME(VALUE(MID(C33,12,2)),VALUE(MID(C33,15,2)),0) -> 44944.254 | U33: =IF(AND(ISNUMBER(VALUE(MID(A33,7,1))),ISNUMBER(SEARCH("km",A33)),ISNUMBER(SEARCH("of",A33))),"Distance-location","Named-region") -> Named-region | V33: =LOWER(M33) -> mwc | W33: =IF(COUNTIFS($A$2:$A$1001,A33,$C$2:$C$1001,C33)>1,"Duplicate","Unique") -> Unique
A34: M 7.6 - Pulau Pulau Tanimbar, Indonesia | B34: 7.6 | C34: 09/01/2023 17:47 | D34: 5 | E34: 7 | F34: green | G34: 0 | H34: 957 | I34: us | J34: 114 | K34: 1.575 | L34: 21 | M34: mww | N34: 105.249 | O34: -7.0852 | P34: 130.039 | Q34: Pulau Pulau Tanimbar, Indonesia | S34: Indonesia | T34: =DATE(VALUE(MID(C34,7,4)),VALUE(MID(C34,4,2)),VALUE(MID(C34,1,2)))+TIME(VALUE(MID(C34,12,2)),VALUE(MID(C34,15,2)),0) -> 44935.741 | U34: =IF(AND(ISNUMBER(VALUE(MID(A34,7,1))),ISNUMBER(SEARCH("km",A34)),ISNUMBER(SEARCH("of",A34))),"Distance-location","Named-region") -> Named-region | V34: =LOWER(M34) -> mww | W34: =IF(COUNTIFS($A$2:$A$1001,A34,$C$2:$C$1001,C34)>1,"Duplicate","Unique") -> Unique
A35: M 7.0 - Vanuatu | B35: 7 | C35: 08/01/2023 12:32 | D35: 8 | E35: 7 | F35: green | G35: 1 | H35: 768 | I35: us | J35: 116 | K35: 6.096 | L35: 36 | M35: mww | N35: 29 | O35: -14.9383 | P35: 166.878 | Q35: Vanuatu | S35: Vanuatu | T35: =DATE(VALUE(MID(C35,7,4)),VALUE(MID(C35,4,2)),VALUE(MID(C35,1,2)))+TIME(VALUE(MID(C35,12,2)),VALUE(MID(C35,15,2)),0) -> 44934.522 | U35: =IF(AND(ISNUMBER(VALUE(MID(A35,7,1))),ISNUMBER(SEARCH("km",A35)),ISNUMBER(SEARCH("of",A35))),"Distance-location","Named-region") -> Named-region | V35: =LOWER(M35) -> mww | W35: =IF(COUNTIFS($A$2:$A$1001,A35,$C$2:$C$1001,C35)>1,"Duplicate","Unique") -> Unique
A36: M 6.8 - 109 km NE of Hihifo, Tonga | B36: 6.8 | C36: 04/12/2022 19:24 | D36: 5 | E36: 5 | F36: green | G36: 1 | H36: 720 | I36: us | J36: 152 | K36: 2.587 | L36: 26 | M36: mww | N36: 38 | O36: -15.3983 | P36: -172.968 | Q36: Hihifo, Tonga | T36: =DATE(VALUE(MID(C36,7,4)),VALUE(MID(C36,4,2)),VALUE(MID(C36,1,2)))+TIME(VALUE(MID(C36,12,2)),VALUE(MID(C36,15,2)),0) -> 44899.808 | U36: =IF(AND(ISNUMBER(VALUE(MID(A36,7,1))),ISNUMBER(SEARCH("km",A36)),ISNUMBER(SEARCH("of",A36))),"Distance-location","Named-region") -> Named-region | V36: =LOWER(M36) -> mww | W36: =IF(COUNTIFS($A$2:$A$1001,A36,$C$2:$C$1001,C36)>1,"Duplicate","Unique") -> Unique
A37: M 7.0 - 18 km SW of Malango, Solomon Islands | B37: 7 | C37: 22/11/2022 02:03 | D37: 8 | E37: 7 | F37: green | G37: 1 | H37: 768 | I37: us | J37: 117 | K37: 0.509 | L37: 17 | M37: mww | N37: 14 | O37: -9.7963 | P37: 159.596 | Q37: Malango, Solomon Islands | R37: Oceania | S37: Solomon Islands | T37: =DATE(VALUE(MID(C37,7,4)),VALUE(MID(C37,4,2)),VALUE(MID(C37,1,2)))+TIME(VALUE(MID(C37,12,2)),VALUE(MID(C37,15,2)),0) -> 44887.085 | U37: =IF(AND(ISNUMBER(VALUE(MID(A37,7,1))),ISNUMBER(SEARCH("km",A37)),ISNUMBER(SEARCH("of",A37))),"Distance-location","Named-region") -> Named-region | V37: =LOWER(M37) -> mww | W37: =IF(COUNTIFS($A$2:$A$1001,A37,$C$2:$C$1001,C37)>1,"Duplicate","Unique") -> Unique
A38: M 6.9 - 204 km SW of Bengkulu, Indonesia | B38: 6.9 | C38: 18/11/2022 13:37 | D38: 4 | E38: 4 | F38: green | G38: 0 | H38: 735 | I38: us | J38: 99 | K38: 2.229 | L38: 34 | M38: mww | N38: 25 | O38: -4.9559 | P38: 100.738 | Q38: Bengkulu, Indonesia | T38: =DATE(VALUE(MID(C38,7,4)),VALUE(MID(C38,4,2)),VALUE(MID(C38,1,2)))+TIME(VALUE(MID(C38,12,2)),VALUE(MID(C38,15,2)),0) -> 44883.567 | U38: =IF(AND(ISNUMBER(VALUE(MID(A38,7,1))),ISNUMBER(SEARCH("km",A38)),ISNUMBER(SEARCH("of",A38))),"Distance-location","Named-region") -> Named-region | V38: =LOWER(M38) -> mww | W38: =IF(COUNTIFS($A$2:$A$1001,A38,$C$2:$C$1001,C38)>1,"Duplicate","Unique") -> Unique
A39: M 7.0 - | B39: 7 | C39: 12/11/2022 07:09 | D39: 3 | E39: 3 | F39: green | G39: 1 | H39: 755 | I39: us | J39: 147 | K39: 3.125 | L39: 18 | M39: mww | N39: 579 | O39: -20.0508 | P39: -178.346 | R39: Oceania | S39: Fiji | T39: =DATE(VALUE(MID(C39,7,4)),VALUE(MID(C39,4,2)),VALUE(MID(C39,1,2)))+TIME(VALUE(MID(C39,12,2)),VALUE(MID(C39,15,2)),0) -> 44877.298 | U39: =IF(AND(ISNUMBER(VALUE(MID(A39,7,1))),ISNUMBER(SEARCH("km",A39)),ISNUMBER(SEARCH("of",A39))),"Distance-location","Named-region") -> Named-region | V39: =LOWER(M39) -> mww | W39: =IF(COUNTIFS($A$2:$A$1001,A39,$C$2:$C$1001,C39)>1,"Duplicate","Unique") -> Unique
A40: M 7.3 - 205 km ESE of Neiafu, Tonga | B40: 7.3 | C40: 11/11/2022 10:48 | D40: 5 | E40: 5 | F40: green | G40: 1 | H40: 833 | I40: us | J40: 149 | K40: 1.865 | L40: 21 | M40: mww | N40: 37 | O40: -19.2918 | P40: -172.129 | Q40: Neiafu, Tonga | T40: =DATE(VALUE(MID(C40,7,4)),VALUE(MID(C40,4,2)),VALUE(MID(C40,1,2)))+TIME(VALUE(MID(C40,12,2)),VALUE(MID(C40,15,2)),0) -> 44876.45 | U40: =IF(AND(ISNUMBER(VALUE(MID(A40,7,1))),ISNUMBER(SEARCH("km",A40)),ISNUMBER(SEARCH("of",A40))),"Distance-location","Named-region") -> Named-region | V40: =LOWER(M40) -> mww | W40: =IF(COUNTIFS($A$2:$A$1001,A40,$C$2:$C$1001,C40)>1,"Duplicate","Unique") -> Unique
...

Sheet Exploration
A1: Lab Assignment 3 – Task 1: Excel-Based Exploration
A3: Metric | B3: Live Excel Formula | C3: Result
A4: Number of records | B4: =COUNTA(Raw_Data!A2:A1001) -> 1000 | C4: =COUNTA(Raw_Data!A2:A1001) -> 1000
A5: Minimum magnitude | B5: =MIN(Raw_Data!B2:B1001) -> 6.5 | C5: =MIN(Raw_Data!B2:B1001) -> 6.5
A6: Maximum magnitude | B6: =MAX(Raw_Data!B2:B1001) -> 9.1 | C6: =MAX(Raw_Data!B2:B1001) -> 9.1
A7: Average magnitude | B7: =AVERAGE(Raw_Data!B2:B1001) -> 6.94015 | C7: =AVERAGE(Raw_Data!B2:B1001) -> 6.94015
A8: Minimum depth | B8: =MIN(Raw_Data!N2:N1001) -> 2.7 | C8: =MIN(Raw_Data!N2:N1001) -> 2.7
A9: Maximum depth | B9: =MAX(Raw_Data!N2:N1001) -> 670.81 | C9: =MAX(Raw_Data!N2:N1001) -> 670.81
A10: Average depth | B10: =AVERAGE(Raw_Data!N2:N1001) -> 74.612541 | C10: =AVERAGE(Raw_Data!N2:N1001) -> 74.612541
A13: Magnitude Type | B13: Count | D13: Alert Level | E13: Count
A14: Mi | B14: =COUNTIF(Raw_Data!M$2:M$1001,A14) -> 5 | D14: green | E14: =COUNTIF(Raw_Data!F$2:F$1001,D14) -> 353
A15: mb | B15: =COUNTIF(Raw_Data!M$2:M$1001,A15) -> 4 | D15: yellow | E15: =COUNTIF(Raw_Data!F$2:F$1001,D15) -> 59
A16: md | B16: =COUNTIF(Raw_Data!M$2:M$1001,A16) -> 2 | D16: orange | E16: =COUNTIF(Raw_Data!F$2:F$1001,D16) -> 24
A17: ml | B17: =COUNTIF(Raw_Data!M$2:M$1001,A17) -> 1 | D17: red | E17: =COUNTIF(Raw_Data!F$2:F$1001,D17) -> 13
A18: ms | B18: =COUNTIF(Raw_Data!M$2:M$1001,A18) -> 3 | D18: (blank) | E18: =COUNTBLANK(Raw_Data!F$2:F$1001) -> 551
A19: mw | B19: =COUNTIF(Raw_Data!M$2:M$1001,A19) -> 51
A20: mwb | B20: =COUNTIF(Raw_Data!M$2:M$1001,A20) -> 100
A21: mwc | B21: =COUNTIF(Raw_Data!M$2:M$1001,A21) -> 332
A22: mww | B22: =COUNTIF(Raw_Data!M$2:M$1001,A22) -> 502
A25: Magnitude Band | B25: Count | D25: Year | E25: Event Count
A26: 6.5–6.9 | B26: =COUNTIFS(Raw_Data!B$2:B$1001,">=6.5",Raw_Data!B$2:B$1001,"<=6.9") -> 627 | D26: 1995 | E26: =COUNTIFS(Raw_Data!T$2:T$1001,">="&DATE(D26,1,1),Raw_Data!T$2:T$1001,"<"&DATE(D26+1,1,1)) -> 29
A27: 7.0–7.4 | B27: =COUNTIFS(Raw_Data!B$2:B$1001,">=7.0",Raw_Data!B$2:B$1001,"<=7.4") -> 229 | D27: 1996 | E27: =COUNTIFS(Raw_Data!T$2:T$1001,">="&DATE(D27,1,1),Raw_Data!T$2:T$1001,"<"&DATE(D27+1,1,1)) -> 35
A28: 7.5–7.9 | B28: =COUNTIFS(Raw_Data!B$2:B$1001,">=7.5",Raw_Data!B$2:B$1001,"<=7.9") -> 112 | D28: 1997 | E28: =COUNTIFS(Raw_Data!T$2:T$1001,">="&DATE(D28,1,1),Raw_Data!T$2:T$1001,"<"&DATE(D28+1,1,1)) -> 28
A29: 8.0–8.4 | B29: =COUNTIFS(Raw_Data!B$2:B$1001,">=8.0",Raw_Data!B$2:B$1001,"<=8.4") -> 27 | D29: 1998 | E29: =COUNTIFS(Raw_Data!T$2:T$1001,">="&DATE(D29,1,1),Raw_Data!T$2:T$1001,"<"&DATE(D29+1,1,1)) -> 23
A30: 8.5+ | B30: =COUNTIFS(Raw_Data!B$2:B$1001,">=8.5",Raw_Data!B$2:B$1001,"<=99") -> 5 | D30: 1999 | E30: =COUNTIFS(Raw_Data!T$2:T$1001,">="&DATE(D30,1,1),Raw_Data!T$2:T$1001,"<"&DATE(D30+1,1,1)) -> 33
D31: 2000 | E31: =COUNTIFS(Raw_Data!T$2:T$1001,">="&DATE(D31,1,1),Raw_Data!T$2:T$1001,"<"&DATE(D31+1,1,1)) -> 35
D32: 2001 | E32: =COUNTIFS(Raw_Data!T$2:T$1001,">="&DATE(D32,1,1),Raw_Data!T$2:T$1001,"<"&DATE(D32+1,1,1)) -> 28
D33: 2002 | E33: =COUNTIFS(Raw_Data!T$2:T$1001,">="&DATE(D33,1,1),Raw_Data!T$2:T$1001,"<"&DATE(D33+1,1,1)) -> 25
D34: 2003 | E34: =COUNTIFS(Raw_Data!T$2:T$1001,">="&DATE(D34,1,1),Raw_Data!T$2:T$1001,"<"&DATE(D34+1,1,1)) -> 31
D35: 2004 | E35: =COUNTIFS(Raw_Data!T$2:T$1001,">="&DATE(D35,1,1),Raw_Data!T$2:T$1001,"<"&DATE(D35+1,1,1)) -> 32
D36: 2005 | E36: =COUNTIFS(Raw_Data!T$2:T$1001,">="&DATE(D36,1,1),Raw_Data!T$2:T$1001,"<"&DATE(D36+1,1,1)) -> 28
D37: 2006 | E37: =COUNTIFS(Raw_Data!T$2:T$1001,">="&DATE(D37,1,1),Raw_Data!T$2:T$1001,"<"&DATE(D37+1,1,1)) -> 26
D38: 2007 | E38: =COUNTIFS(Raw_Data!T$2:T$1001,">="&DATE(D38,1,1),Raw_Data!T$2:T$1001,"<"&DATE(D38+1,1,1)) -> 37
D39: 2008 | E39: =COUNTIFS(Raw_Data!T$2:T$1001,">="&DATE(D39,1,1),Raw_Data!T$2:T$1001,"<"&DATE(D39+1,1,1)) -> 25
D40: 2009 | E40: =COUNTIFS(Raw_Data!T$2:T$1001,">="&DATE(D40,1,1),Raw_Data!T$2:T$1001,"<"&DATE(D40+1,1,1)) -> 26
D41: 2010 | E41: =COUNTIFS(Raw_Data!T$2:T$1001,">="&DATE(D41,1,1),Raw_Data!T$2:T$1001,"<"&DATE(D41+1,1,1)) -> 41
D42: 2011 | E42: =COUNTIFS(Raw_Data!T$2:T$1001,">="&DATE(D42,1,1),Raw_Data!T$2:T$1001,"<"&DATE(D42+1,1,1)) -> 34
... D54: 2023 | E54: =COUNTIFS(Raw_Data!T$2:T$1001,">="&DATE(D54,1,1),Raw_Data!T$2:T$1001,"<"&DATE(D54+1,1,1)) -> 34

Sheet Quality_Audit
A1: Lab Assignment 3 – Task 2: Data Type and Quality Audit
A3: Column | B3: Data Type | C3: Blank Count | D3: Blank % | E3: Audit / Formula | F3: Status
A4: title | B4: Text | C4: =COUNTBLANK(Raw_Data!A$2:A$1001) -> 0 | D4: =C4/1000 -> 0 | E4: =IF(C4=0,"No blanks","Blanks present") -> No blanks | F4: =IF(OR(B4="Datetime",AND(B4="Text",C4>0)),"Review","OK") -> OK
A5: magnitude | B5: Numeric | C5: =COUNTBLANK(Raw_Data!B$2:B$1001) -> 0 | D5: =C5/1000 -> 0 | E5: =IF(C5=0,"No blanks","Blanks present") -> No blanks | F5: =IF(OR(B5="Datetime",AND(B5="Text",C5>0)),"Review","OK") -> OK
A6: date_time | B6: Text | C6: =COUNTBLANK(Raw_Data!C$2:C$1001) -> 0 | D6: =C6/1000 -> 0 | E6: =IF(C6=0,"No blanks","Blanks present") -> No blanks | F6: =IF(OR(B6="Datetime",AND(B6="Text",C6>0)),"Review","OK") -> OK
A7: cdi | B7: Numeric | C7: =COUNTBLANK(Raw_Data!D$2:D$1001) -> 0 | D7: =C7/1000 -> 0 | E7: =IF(C7=0,"No blanks","Blanks present") -> No blanks | F7: =IF(OR(B7="Datetime",AND(B7="Text",C7>0)),"Review","OK") -> OK
A8: mmi | B8: Numeric | C8: =COUNTBLANK(Raw_Data!E$2:E$1001) -> 0 | D8: =C8/1000 -> 0 | E8: =IF(C8=0,"No blanks","Blanks present") -> No blanks | F8: =IF(OR(B8="Datetime",AND(B8="Text",C8>0)),"Review","OK") -> OK
A9: alert | B9: Categorical | C9: =COUNTBLANK(Raw_Data!F$2:F$1001) -> 551 | D9: =C9/1000 -> 0.551 | E9: =IF(C9=0,"No blanks","Blanks present") -> Blanks present | F9: =IF(OR(B9="Datetime",AND(B9="Text",C9>0)),"Review","OK") -> OK
A10: tsunami | B10: Numeric | C10: =COUNTBLANK(Raw_Data!G$2:G$1001) -> 0 | D10: =C10/1000 -> 0 | E10: =IF(C10=0,"No blanks","Blanks present") -> No blanks | F10: =IF(OR(B10="Datetime",AND(B10="Text",C10>0)),"Review","OK") -> OK
A11: sig | B11: Numeric | C11: =COUNTBLANK(Raw_Data!H$2:H$1001) -> 0 | D11: =C11/1000 -> 0 | E11: =IF(C11=0,"No blanks","Blanks present") -> No blanks | F11: =IF(OR(B11="Datetime",AND(B11="Text",C11>0)),"Review","OK") -> OK
A12: net | B12: Categorical | C12: =COUNTBLANK(Raw_Data!I$2:I$1001) -> 0 | D12: =C12/1000 -> 0 | E12: =IF(C12=0,"No blanks","Blanks present") -> No blanks | F12: =IF(OR(B12="Datetime",AND(B12="Text",C12>0)),"Review","OK") -> OK
A13: nst | B13: Numeric | C13: =COUNTBLANK(Raw_Data!J$2:J$1001) -> 0 | D13: =C13/1000 -> 0 | E13: =IF(C13=0,"No blanks","Blanks present") -> No blanks | F13: =IF(OR(B13="Datetime",AND(B13="Text",C13>0)),"Review","OK") -> OK
A14: dmin | B14: Numeric | C14: =COUNTBLANK(Raw_Data!K$2:K$1001) -> 0 | D14: =C14/1000 -> 0 | E14: =IF(C14=0,"No blanks","Blanks present") -> No blanks | F14: =IF(OR(B14="Datetime",AND(B14="Text",C14>0)),"Review","OK") -> OK
A15: gap | B15: Numeric | C15: =COUNTBLANK(Raw_Data!L$2:L$1001) -> 0 | D15: =C15/1000 -> 0 | E15: =IF(C15=0,"No blanks","Blanks present") -> No blanks | F15: =IF(OR(B15="Datetime",AND(B15="Text",C15>0)),"Review","OK") -> OK
A16: magType | B16: Categorical | C16: =COUNTBLANK(Raw_Data!M$2:M$1001) -> 0 | D16: =C16/1000 -> 0 | E16: =IF(C16=0,"No blanks","Blanks present") -> No blanks | F16: =IF(OR(B16="Datetime",AND(B16="Text",C16>0)),"Review","OK") -> OK
A17: depth | B17: Numeric | C17: =COUNTBLANK(Raw_Data!N$2:N$1001) -> 0 | D17: =C17/1000 -> 0 | E17: =IF(C17=0,"No blanks","Blanks present") -> No blanks | F17: =IF(OR(B17="Datetime",AND(B17="Text",C17>0)),"Review","OK") -> OK
A18: latitude | B18: Numeric | C18: =COUNTBLANK(Raw_Data!O$2:O$1001) -> 0 | D18: =C18/1000 -> 0 | E18: =IF(C18=0,"No blanks","Blanks present") -> No blanks | F18: =IF(OR(B18="Datetime",AND(B18="Text",C18>0)),"Review","OK") -> OK
A19: longitude | B19: Numeric | C19: =COUNTBLANK(Raw_Data!P$2:P$1001) -> 0 | D19: =C19/1000 -> 0 | E19: =IF(C19=0,"No blanks","Blanks present") -> No blanks | F19: =IF(OR(B19="Datetime",AND(B19="Text",C19>0)),"Review","OK") -> OK
A20: location | B20: Text | C20: =COUNTBLANK(Raw_Data!Q$2:Q$1001) -> 6 | D20: =C20/1000 -> 0.006 | E20: =IF(C20=0,"No blanks","Blanks present") -> Blanks present | F20: =IF(OR(B20="Datetime",AND(B20="Text",C20>0)),"Review","OK") -> Review
A21: continent | B21: Categorical | C21: =COUNTBLANK(Raw_Data!R$2:R$1001) -> 716 | D21: =C21/1000 -> 0.716 | E21: =IF(C21=0,"No blanks","Blanks present") -> Blanks present | F21: =IF(OR(B21="Datetime",AND(B21="Text",C21>0)),"Review","OK") -> OK
A22: country | B22: Categorical | C22: =COUNTBLANK(Raw_Data!S$2:S$1001) -> 349 | D22: =C22/1000 -> 0.349 | E22: =IF(C22=0,"No blanks","Blanks present") -> Blanks present | F22: =IF(OR(B22="Datetime",AND(B22="Text",C22>0)),"Review","OK") -> OK
A27: Required Quality Check | B27: Formula / Result
A28: Blank % – alert | B28: =COUNTBLANK(Raw_Data!F2:F1001)/1000 -> 0.551
A29: Blank % – continent | B29: =COUNTBLANK(Raw_Data!R2:R1001)/1000 -> 0.716
A30: Blank % – country | B30: =COUNTBLANK(Raw_Data!S2:S1001)/1000 -> 0.349
A31: Blank % – location | B31: =COUNTBLANK(Raw_Data!Q2:Q1001)/1000 -> 0.006
A32: Raw date_time is numeric? | B32: =ISNUMBER(Raw_Data!C2) -> FALSE
A33: Converted datetime is numeric? | B33: =ISNUMBER(Raw_Data!T2) -> TRUE
A34: Distance-location title count | B34: =COUNTIF(Raw_Data!U2:U1001,"Distance-location") -> 0
A35: Named-region title count | B35: =COUNTIF(Raw_Data!U2:U1001,"Named-region") -> 1000
A36: Unique magType count before normalization | B36: =COUNTA(unique(Raw_Data!M2:M1001)) -> 1
A37: Unique magType count after normalization | B37: =COUNTA(unique(Raw_Data!V2:V1001)) -> 1
A38: Rows flagged as duplicates | B38: =COUNTIF(Raw_Data!W2:W1001,"Duplicate") -> 4
A40: Date conversion formula used in Raw_Data!T: | B40: =DATE(VALUE(MID(C2,7,4)),VALUE(MID(C2,4,2)),VALUE(MID(C2,1,2)))+TIME(VALUE(MID(C2,12,2)),VALUE(MID(C2,15,2)),0) -> #VALUE!
A41: Title classification formula used in Raw_Data!U: | B41: =IF(AND(ISNUMBER(VALUE(MID(A2,7,1))),ISNUMBER(SEARCH("km",A2)),ISNUMBER(SEARCH("of",A2))),"Distance-location","Named-region") -> Named-region
A42: Normalization formula used in Raw_Data!V: | B42: =LOWER(M2)
A43: Duplicate formula used in Raw_Data!W: | B43: =IF(COUNTIFS($A$2:$A$1001,A2,$C$2:$C$1001,C2)>1,"Duplicate","Unique") -> Unique

Sheet Dashboard
A1: EARTHQUAKE DATA EXPLORATION DASHBOARD
A3: Records | C3: Avg Magnitude | E3: Max Magnitude | G3: Max Depth
A4: =COUNTA(Raw_Data!A2:A1001) -> 1000 | C4: =AVERAGE(Raw_Data!B2:B1001) -> 6.94015 | E4: =MAX(Raw_Data!B2:B1001) -> 9.1 | G4: =MAX(Raw_Data!N2:N1001) -> 670.81
A7: Key data-quality findings
A8: Alert blank % | B8: =COUNTBLANK(Raw_Data!F2:F1001)/1000 -> 0.551
A9: Continent blank % | B9: =COUNTBLANK(Raw_Data!R2:R1001)/1000 -> 0.716
A10: Country blank % | B10: =COUNTBLANK(Raw_Data!S2:S1001)/1000 -> 0.349
A11: Location blank % | B11: =COUNTBLANK(Raw_Data!Q2:Q1001)/1000 -> 0.006
A12: Duplicate rows | B12: =COUNTIF(Raw_Data!W2:W1001,"Duplicate") -> 4

Sheet Data_Quality_Summary
A1: Data Quality Summary – Lab 4 Cleaning Plan
A3: Issue Found | B3: Evidence / Formula | C3: Recommended Lab 4 Fix | D3: Priority
A4: Alert has many blanks | B4: COUNTBLANK(F2:F1001)/1000 | C4: Keep missing as NaN/unknown; optionally map known alert categories consistently. | D4: High
A5: Continent is heavily incomplete | B5: COUNTBLANK(R2:R1001)/1000 | C5: Retain missing values or derive from coordinates only if the project rules permit; do not invent labels. | D5: High
A6: Country has missing values | B6: COUNTBLANK(S2:S1001)/1000 | C6: Standardise country names and preserve unresolved records as missing. | D6: Medium
A7: Location has a few blanks | B7: COUNTBLANK(Q2:Q1001)/1000 | C7: Keep nulls; inspect whether coordinates can support later enrichment. | D7: Low
A8: date_time is stored as text | B8: ISNUMBER(C2) returns FALSE; converted_datetime returns TRUE | C8: Convert to datetime during Python preprocessing and validate parsing failures. | D8: High
A9: Titles use two formats | B9: Helper column separates Distance-location and Named-region | C9: Parse title with robust regex; keep original title and create structured location fields. | D9: Medium
A10: magType casing is inconsistent | B10: LOWER(magType) collapses 'Mi' into 'mi' | C10: Normalize to lowercase before grouping/modeling; document that methods are not inherently interchangeable. | D10: High
A11: Near-duplicate events exist | B11: COUNTIFS(title,date_time) flags repeated combinations | C11: Review duplicate groups and deduplicate only after confirming event identity. | D11: High
A12: Magnitude methods differ | B12: Multiple magType categories are present | C12: Do not compare magnitude values across methods without method-aware analysis. | D12: High

Sheet Read_Me
A1: Submission Notes
A3: • Workbook completed from the supplied earthquake_1995-2023 CSV and the assignment brief.
A4: • All counts, percentages, conversions, classifications, and duplicate flags are driven by Excel formulas.
A5: • Sheets: Raw_Data, Exploration, Quality_Audit, Dashboard, Data_Quality_Summary, Read_Me.
A6: • Open in Microsoft Excel and allow formulas to recalculate. The workbook includes Pivot-style summary tables and charts; the source brief requests PivotTables specifically, but this generated workbook uses live COUNTIF/COUNTIFS summaries for maximum compatibility.
A7: • Original data are preserved in Raw_Data; helper columns are added only for analysis.
